<robot name="HumanModel">

  <material name="color">
    <color rgba="0.9922 0.8667 0.7922 1.    "/>
  </material>
  <material name="muscle">
    <color rgba="1.0 0.0 0.0 1.    "/>
  </material>

<!--LINKS-->

##############################################################################
# PELVI  ORIGIN
##############################################################################
	<!--Link base (1)-->
	<link name="Pelvis">
        <inertial>
            <mass value="1e-5"/>
            <!--box origin wrt Pelvis-->
            <origin xyz="0 0 0" rpy="0 0 0" />
            <inertia ixx="0.0" ixy="0.0" ixz="0.0" iyy="0.0" iyz="0.0" izz="0.0"/>
        </inertial>

        <visual>
			<!--box origin wrt Pelvis-->
            <origin xyz="0 0 0" rpy="0 0 0" />
            <geometry>
                <box size="1 1 1"/>
            </geometry>
            <material name="color"/>
        </visual>

        <collision>
			<!--box origin wrt Pelvis-->
            <origin xyz="0 0 0" rpy="0 0 0" />
            <geometry>
                <box size="1 1 1"/>
            </geometry>
        </collision>
    </link>
##############################################################################
# PELVI - LOWERTRUNK
##############################################################################
	<link name="LowerTrunk_f1">
        <inertial>
            <mass value="1e-5"/>
            <origin xyz="0 0 0" rpy="0 0 0" />
            <inertia ixx="0.0" ixy="0.0" ixz="0.0" iyy="0.0" iyz="0.0" izz="0.0"/>
        </inertial>
    </link>
##############################################################################
# LOWERTRUNK
##############################################################################
	<link name="LowerTrunk">
        <inertial>
            <mass value="1e-5"/>
			<!--COM origin wrt LowerTrunk-->
            <origin xyz="0 0 0" rpy="0 0 0" />
            <inertia ixx="0.0" ixy="0.0" ixz="0.0" iyy="0.0" iyz="0.0" izz="0.0"/>
        </inertial>

        <visual>
			<!--box origin origin wrt jL5S1-->
            <origin xyz="0 0 0" rpy="0 0 0" />
            <geometry>
                <box size="1 1 1"/>
            </geometry>
            <material name="color"/>
        </visual>

        <collision>
			<!--box origin origin wrt jL5S1-->
            <origin xyz="0 0 0" rpy="0 0 0" />
            <geometry>
                <box size="1 1 1"/>
            </geometry>
        </collision>
    </link>
##############################################################################
# LOWERTRUNK - UPPERTRUNK
##############################################################################
	<link name="UpperTrunk_f1">
        <inertial>
            <mass value="1e-5"/>
            <origin xyz="0 0 0" rpy="0 0 0" />
            <inertia ixx="0.0" ixy="0.0" ixz="0.0" iyy="0.0" iyz="0.0" izz="0.0"/>
        </inertial>
    </link>
	<link name="UpperTrunk_f2">
        <inertial>
            <mass value="1e-5"/>
            <origin xyz="0 0 0" rpy="0 0 0" />
            <inertia ixx="0.0" ixy="0.0" ixz="0.0" iyy="0.0" iyz="0.0" izz="0.0"/>
        </inertial>
    </link>
##############################################################################
# UPPERTRUNK
##############################################################################
	<link name="UpperTrunk">
        <inertial>
            <mass value="1e-5"/>
			<!--COM origin wrt jL4L3-->
            <origin xyz="0 0 0" rpy="0 0 0" />
            <inertia ixx="0.0" ixy="0.0" ixz="0.0" iyy="0.0" iyz="0.0" izz="0.0"/>
        </inertial>

        <visual>
			<!--box origin origin wrt jL4L3-->
            <origin xyz="0 0 0" rpy="0 0 0" />
            <geometry>
                <box size="1 1 1"/>
            </geometry>
            <material name="color"/>
        </visual>

        <collision>
			<!--box origin origin wrt jL4L3-->
            <origin xyz="0 0 0" rpy="0 0 0" />
            <geometry>
                <box size="1 1 1"/>
            </geometry>
        </collision>
    </link>
##############################################################################
# RIGHTSHOULDER
##############################################################################
	<link name="RightShoulder">
        <inertial>
            <mass value="1e-5"/>
			<!--COM origin wrt jL4L3-->
            <origin xyz="0 0 0" rpy="1.5708 0 0" />
            <inertia ixx="0.0" ixy="0.0" ixz="0.0" iyy="0.0" iyz="0.0" izz="0.0"/>
        </inertial>

        <visual>
			<!--box origin origin wrt jL4L3-->
            <origin xyz="0 0 0" rpy="1.5708 0 0" />
            <geometry>
                <cylinder length="1" radius="1"/>
            </geometry>
            <material name="color"/>
        </visual>

        <collision>
			<!--box origin origin wrt jL4L3-->
            <origin xyz="0 0 0" rpy="1.5708 0 0" />
            <geometry>
                <cylinder length="1" radius="1"/>
            </geometry>
        </collision>
    </link>
##############################################################################
# LEFTSHOULDER
##############################################################################
	<link name="LeftShoulder">
        <inertial>
            <mass value="1e-5"/>
			<!--COM origin wrt jL4L3-->
            <origin xyz="0 0 0" rpy="0 0 0" />
            <inertia ixx="0.0" ixy="0.0" ixz="0.0" iyy="0.0" iyz="0.0" izz="0.0"/>
        </inertial>

        <visual>
			<!--box origin origin wrt jL4L3-->
            <origin xyz="0 0 0" rpy="1.5708 0 0" />
            <geometry>
                <cylinder length="1" radius="1"/>
            </geometry>
            <material name="color"/>
        </visual>

        <collision>
			<!--box origin origin wrt jL4L3-->
            <origin xyz="0 0 0" rpy="1.5708 0 0" />
            <geometry>
                <cylinder length="1" radius="1"/>
            </geometry>
        </collision>
    </link>
##############################################################################
# UPPERTRUNK - NECK
##############################################################################	
	<link name="Neck_f1">
        <inertial>
            <mass value="1e-5"/>
            <origin xyz="0 0 0" rpy="0 0 0" />
            <inertia ixx="0.0" ixy="0.0" ixz="0.0" iyy="0.0" iyz="0.0" izz="0.0"/>
        </inertial>
    </link>
	<link name="Neck_f2">
        <inertial>
            <mass value="1e-5"/>
            <origin xyz="0 0 0" rpy="0 0 0" />
            <inertia ixx="0.0" ixy="0.0" ixz="0.0" iyy="0.0" iyz="0.0" izz="0.0"/>
        </inertial>
    </link>
##############################################################################
# NECK
##############################################################################	
	<link name="Neck">
        <inertial>
            <mass value="1e-5"/>
			<!--COM origin wrt jT1C7-->
            <origin xyz="0 0 0" rpy="0 0 0" />
            <inertia ixx="0.0" ixy="0.0" ixz="0.0" iyy="0.0" iyz="0.0" izz="0.0"/>
        </inertial>

        <visual>
			<!--box origin wrt jT1C7-->
            <origin xyz="0 0 0" rpy="0 0 0" />
            <geometry>
		<cylinder length="1" radius="1"/>
            </geometry>
            <material name="color"/>
        </visual>

        <collision>
			<!--box origin wrt jT1C7-->
            <origin xyz="0 0 0" rpy="0 0 0" />
            <geometry>
                <cylinder length="1" radius="1"/>
            </geometry>
        </collision>
    </link>
##############################################################################
# NECK - HEAD
##############################################################################	
	<link name="Head_f1">
        <inertial>
            <mass value="1e-5"/>
            <origin xyz="0 0 0" rpy="0 0 0" />
            <inertia ixx="0.0" ixy="0.0" ixz="0.0" iyy="0.0" iyz="0.0" izz="0.0"/>
        </inertial>
    </link>
##############################################################################
# HEAD
##############################################################################	
	<link name="Head">
        <inertial>
            <mass value="1e-5"/>
			<!--COM origin wrt jC1Head-->
            <origin xyz="0 0 0" rpy="0 0 0" />
            <inertia ixx="0.0" ixy="0.0" ixz="0.0" iyy="0.0" iyz="0.0" izz="0.0"/>
        </inertial>

        <visual>
			<!--boc origin wrt jC1Head-->
            <origin xyz="0 0 0" rpy="0 0 0" />
            <geometry>
                <sphere radius="1"/>
            </geometry>
            <material name="color"/>
        </visual>

        <collision>
			<!--box origin wrt jC1Head-->
            <origin xyz="0 0 0" rpy="0 0 0" />
            <geometry>
                <sphere radius="1"/>
            </geometry>
        </collision>
    </link>


##############################################################################
# RIGHT SHOULDER
##############################################################################
	<link name="RightShoulder_f1">
        <inertial>
            <mass value="1e-5"/>
            <origin xyz="0 0 0" rpy="0 0 0" />
            <inertia ixx="0.0" ixy="0.0" ixz="0.0" iyy="0.0" iyz="0.0" izz="0.0"/>
        </inertial>
    </link>
	<link name="RightShoulder_f2">
        <inertial>
            <mass value="1e-5"/>
            <origin xyz="0 0 0" rpy="0 0 0" />
            <inertia ixx="0.0" ixy="0.0" ixz="0.0" iyy="0.0" iyz="0.0" izz="0.0"/>
        </inertial>
    </link>
##############################################################################
# RIGHT UPPERARM
##############################################################################
    <link name="RightUpperArm">
        <inertial>
            <mass value="1e-5"/>
			<!--COM origin wrt jRightShoulder-->
            <origin xyz="0 0 0" rpy="0 0 0" />
            <inertia ixx="0.0" ixy="0.0" ixz="0.0" iyy="0.0" iyz="0.0" izz="0.0"/>
        </inertial>

        <visual>
			<!--box origin wrt jRightShoulder. RPY rotated of pi/2.-->
            <origin xyz="0 0 0" rpy="1.5708 0 0" />
            <geometry>
                <cylinder length="1" radius="1"/>
            </geometry>
            <material name="color"/>
        </visual>

        <collision>
			<!--box origin wrt jRightShoulder. RPY rotated of pi/2.-->
            <origin xyz="0 0 0" rpy="1.5708 0 0" />
            <geometry>
                <cylinder length="1" radius="1"/>
            </geometry>
        </collision>
    </link>
##############################################################################
# RIGHT ELBOW
##############################################################################
	<link name="RightForeArm_f1">
        <inertial>
            <mass value="1e-5"/>
            <origin xyz="0 0 0" rpy="0 0 0" />
            <inertia ixx="0.0" ixy="0.0" ixz="0.0" iyy="0.0" iyz="0.0" izz="0.0"/>
        </inertial>
    </link>
##############################################################################
# RIGHT FOREARM
##############################################################################
	<link name="RightForeArm">
        <inertial>
            <mass value="1e-5"/>
			<!--COM origin wrt jRightElbow-->
            <origin xyz="0 0 0" rpy="0 0 0" />
            <inertia ixx="0.0" ixy="0.0" ixz="0.0" iyy="0.0" iyz="0.0" izz="0.0"/>
        </inertial>

        <visual>
			<!--box origin wrt jRightElbow. RPY rotated of pi/2.-->
            <origin xyz="0 0 0" rpy="1.5708 0 0" />
            <geometry>
                <cylinder length="1" radius="1"/>
            </geometry>
            <material name="color"/>
        </visual>

        <collision>
			<!--box origin wrt jRightElbow. RPY rotated of pi/2.-->
            <origin xyz="0 0 0" rpy="1.5708 0 0" />
            <geometry>
                <cylinder length="1" radius="1"/>
            </geometry>
        </collision>
    </link>
##############################################################################
# RIGHT WRIST
##############################################################################
	<link name="RightHand_f1">
        <inertial>
            <mass value="1e-5"/>
            <origin xyz="0 0 0" rpy="0 0 0" />
            <inertia ixx="0.0" ixy="0.0" ixz="0.0" iyy="0.0" iyz="0.0" izz="0.0"/>
        </inertial>
    </link>
##############################################################################
# RIGHT HAND
##############################################################################
	<link name="RightHand">
        <inertial>
            <mass value="1e-5"/>
			<!--COM origin wrt jRightWrist-->
            <origin xyz="0 0 0" rpy="0 0 0" />
            <inertia ixx="0.0" ixy="0.0" ixz="0.0" iyy="0.0" iyz="0.0" izz="0.0"/>
        </inertial>

        <visual>
			<!--box origin wrt jRightWrist-->
            <origin xyz="0 0 0" rpy="0 0 0" />
            <geometry>
                <box size="1 1 1"/>
            </geometry>
            <material name="color"/>
        </visual>

        <collision>
			<!--box origin wrt jRightWrist-->
            <origin xyz="0 0 0" rpy="0 0 0" />
            <geometry>
                <box size="1 1 1"/>
            </geometry>
        </collision>
    </link>
##############################################################################
# RIGHT HAND COM
##############################################################################
    <link name="RightHandCOM">
        <inertial>
            <mass value="1e-05"/>
            <origin xyz="0 0 0" rpy="0 0 0" />
            <inertia ixx="0.0" ixy="0.0" ixz="0.0" iyy="0.0" iyz="0.0" izz="0.0"/>
        </inertial>
        <visual>
            <!--box origin wrt jRightWrist-->
            <origin xyz="0 0 0" rpy="0 0 0" />
            <geometry>
                <box size="0 0 0"/>
            </geometry>
            <material name="color"/>
        </visual>
    </link>


##############################################################################
# LEFT SHOULDER
##############################################################################
	<link name="LeftShoulder_f1">
        <inertial>
            <mass value="1e-5"/>
            <origin xyz="0 0 0" rpy="0 0 0" />
            <inertia ixx="0.0" ixy="0.0" ixz="0.0" iyy="0.0" iyz="0.0" izz="0.0"/>
        </inertial>
    </link>
	<link name="LeftShoulder_f2">
        <inertial>
            <mass value="1e-5"/>
            <origin xyz="0 0 0" rpy="0 0 0" />
            <inertia ixx="0.0" ixy="0.0" ixz="0.0" iyy="0.0" iyz="0.0" izz="0.0"/>
        </inertial>
    </link>
##############################################################################
# LEFT UPPERARM
##############################################################################

	<link name="LeftUpperArm">
        <inertial>
            <mass value="1e-5"/>
			<!--COM origin wrt jLeftShoulder-->
            <origin xyz="0 0 0" rpy="0 0 0" />
            <inertia ixx="0.0" ixy="0.0" ixz="0.0" iyy="0.0" iyz="0.0" izz="0.0"/>
        </inertial>

        <visual>
			<!--box origin wrt jLeftShoulder. RPY rotated of pi/2.-->
            <origin xyz="0 0 0" rpy="1.5708 0 0" />
            <geometry>
                <cylinder length="1" radius="1"/>
            </geometry>
            <material name="color"/>
        </visual>

        <collision>
			<!--box origin wrt jLeftShoulder. RPY rotated of pi/2.-->
            <origin xyz="0 0 0" rpy="1.5708 0 0" />
            <geometry>
                <cylinder length="1" radius="1"/>
            </geometry>
        </collision>
    </link>
##############################################################################
# LEFT ELBOW
##############################################################################
	<link name="LeftForeArm_f1">
        <inertial>
            <mass value="1e-5"/>
            <origin xyz="0 0 0" rpy="0 0 0" />
            <inertia ixx="0.0" ixy="0.0" ixz="0.0" iyy="0.0" iyz="0.0" izz="0.0"/>
        </inertial>
    </link>
##############################################################################
# LEFT FOREARM
##############################################################################
	<link name="LeftForeArm">
        <inertial>
            <mass value="1e-5"/>
			<!--COM origin wrt jLeftElbow-->
            <origin xyz="0 0 0" rpy="0 0 0" />
            <inertia ixx="0.0" ixy="0.0" ixz="0.0" iyy="0.0" iyz="0.0" izz="0.0"/>
        </inertial>

        <visual>
			<!--box origin wrt jLeftElbow. RPY rotated of pi/2.-->
            <origin xyz="0 0 0" rpy="1.5708 0 0" />
            <geometry>
                <cylinder length="1" radius="1"/>
            </geometry>
            <material name="color"/>
        </visual>

        <collision>
			<!--box origin wrt jLeftElbow. RPY rotated of pi/2.-->
            <origin xyz="0 0 0" rpy="1.5708 0 0" />
            <geometry>
                <cylinder length="1" radius="1"/>
            </geometry>
        </collision>
    </link>
##############################################################################
# LEFT WRIST
##############################################################################
	<link name="LeftHand_f1">
        <inertial>
            <mass value="1e-5"/>
            <origin xyz="0 0 0" rpy="0 0 0" />
            <inertia ixx="0.0" ixy="0.0" ixz="0.0" iyy="0.0" iyz="0.0" izz="0.0"/>
        </inertial>
    </link>
##############################################################################
# LEFT HAND
##############################################################################
	<link name="LeftHand">
        <inertial>
            <mass value="1e-5"/>
			<!--COM origin wrt jLeftWrist-->
            <origin xyz="0 0 0" rpy="0 0 0" />
            <inertia ixx="0.0" ixy="0.0" ixz="0.0" iyy="0.0" iyz="0.0" izz="0.0"/>
        </inertial>

        <visual>
			<!--COM origin wrt jLeftWrist-->
            <origin xyz="0 0 0" rpy="0 0 0" />
            <geometry>
                <box size="1 1 1"/>
            </geometry>
            <material name="color"/>
        </visual>

        <collision>
			<!--COM origin wrt jLeftWrist-->
            <origin xyz="0 0 0" rpy="0 0 0" />
            <geometry>
                <box size="1 1 1"/>
            </geometry>
        </collision>

    </link>
##############################################################################
# LEFT HAND COM
##############################################################################
    <link name="LeftHandCOM">
        <inertial>
            <mass value="1e-05"/>
            <origin xyz="0 0 0" rpy="0 0 0" />
            <inertia ixx="0.0" ixy="0.0" ixz="0.0" iyy="0.0" iyz="0.0" izz="0.0"/>
        </inertial>
        <visual>
            <!--COM origin wrt jLeftWrist-->
            <origin xyz="0 0 0" rpy="0 0 0" />
            <geometry>
                <box size="0 0 0"/>
            </geometry>
            <material name="color"/>
        </visual>
    </link>


##############################################################################
# RIGHT HIP
##############################################################################
	<link name="RightUpperLeg_f1">
        <inertial>
            <mass value="1e-5"/>
            <origin xyz="0 0 0" rpy="0 0 0" />
            <inertia ixx="0.0" ixy="0.0" ixz="0.0" iyy="0.0" iyz="0.0" izz="0.0"/>
        </inertial>
    </link>
	<link name="RightUpperLeg_f2">
        <inertial>
            <mass value="1e-5"/>
            <origin xyz="0 0 0" rpy="0 0 0" />
            <inertia ixx="0.0" ixy="0.0" ixz="0.0" iyy="0.0" iyz="0.0" izz="0.0"/>
        </inertial>
    </link>
##############################################################################
# RIGHT UPPERLEG
##############################################################################
    <link name="RightUpperLeg">
        <inertial>
            <mass value="1e-5"/>
			<!--COM origin wrt jRightHip-->
            <origin xyz="0 0 0" rpy="0 0 0" />
            <inertia ixx="0.0" ixy="0.0" ixz="0.0" iyy="0.0" iyz="0.0" izz="0.0"/>
        </inertial>

        <visual>
			<!--box origin wrt jRightHip-->
            <origin xyz="0 0 0" rpy="0 0 0" />
            <geometry>
                <cylinder length="1" radius="1"/>
            </geometry>
            <material name="color"/>
        </visual>

        <collision>
			<!--box origin wrt jRightHip-->
            <origin xyz="0 0 0" rpy="0 0 0" />
            <geometry>
                <cylinder length="1" radius="1"/>
            </geometry>
        </collision>
     </link>
##############################################################################
# RIGHT KNEE
##############################################################################
	<link name="RightLowerLeg_f1">
        <inertial>
            <mass value="1e-5"/>
            <origin xyz="0 0 0" rpy="0 0 0" />
            <inertia ixx="0.0" ixy="0.0" ixz="0.0" iyy="0.0" iyz="0.0" izz="0.0"/>
        </inertial>
    </link>
##############################################################################
# RIGHT LOWERLEG
##############################################################################
    <link name="RightLowerLeg">
        <inertial>
            <mass value="1e-5"/>
			<!--COM origin wrt jRightKnee-->
            <origin xyz="0 0 0" rpy="0 0 0" />
            <inertia ixx="0.0" ixy="0.0" ixz="0.0" iyy="0.0" iyz="0.0" izz="0.0"/>
        </inertial>

        <visual>
			<!--box origin wrt jRightKnee-->
            <origin xyz="0 0 0" rpy="0 0 0" />
            <geometry>
                <cylinder length="1" radius="1"/>
            </geometry>
            <material name="color"/>
        </visual>

        <collision>
			<!--box origin wrt jRightKnee-->
            <origin xyz="0 0 0" rpy="0 0 0" />
            <geometry>
                <cylinder length="1" radius="1"/>
            </geometry>
        </collision>
    </link>
##############################################################################
# RIGHT ANKLE
############################################################################## 
	<link name="RightFoot_f1">
        <inertial>
            <mass value="1e-5"/>
            <origin xyz="0 0 0" rpy="0 0 0" />
            <inertia ixx="0.0" ixy="0.0" ixz="0.0" iyy="0.0" iyz="0.0" izz="0.0"/>
        </inertial>
    </link>
	<link name="RightFoot_f2">
        <inertial>
            <mass value="1e-5"/>
            <origin xyz="0 0 0" rpy="0 0 0" />
            <inertia ixx="0.0" ixy="0.0" ixz="0.0" iyy="0.0" iyz="0.0" izz="0.0"/>
        </inertial>
    </link>
##############################################################################
# RIGHT FOOT
##############################################################################
    <link name="RightFoot">
        <inertial>
            <mass value="1e-5"/>
			<!--COM origin wrt jRightAnkle-->
            <origin xyz="0 0 0" rpy="0 0 0" />
            <inertia ixx="0.0" ixy="0.0" ixz="0.0" iyy="0.0" iyz="0.0" izz="0.0"/>
        </inertial>

        <visual>
			<!--box origin wrt jRightAnkle-->
            <origin xyz="0 0 0" rpy="0 0 0" />
            <geometry>
                <box size="1 1 1"/>
            </geometry>
            <material name="color"/>
        </visual>

        <collision>
			<!--box origin wrt jRightAnkle-->
            <origin xyz="0 0 0" rpy="0 0 0" />
	        <geometry>
                <box size="1 1 1"/>
	        </geometry>
        </collision>

    </link>
##############################################################################
# RIGHT TOE
##############################################################################
    <link name="RightToe">
        <inertial>
            <mass value="1e-5"/>
			<!--COM origin wrt jRightBallFoot-->
            <origin xyz="0 0 0" rpy="0 0 0" />
            <inertia ixx="0.0" ixy="0.0" ixz="0.0" iyy="0.0" iyz="0.0" izz="0.0"/>
        </inertial>

        <visual>
			<!--box origin wrt jRightBallFoot-->
            <origin xyz="0 0 0" rpy="0 0 0" />
            <geometry>
                <box size="1 1 1"/>
            </geometry>
            <material name="color"/>
        </visual>

        <collision>
			<!--box origin wrt jRightBallFoot-->
            <origin xyz="0 0 0" rpy="0 0 0" />
	        <geometry>
                <box size="1 1 1"/>
	        </geometry>
        </collision>
    </link>
##############################################################################
# RIGHT FTSENSOR
##############################################################################
    <link name="RightFTSensor">
        <inertial>
            <mass value="1e-05"/>
            <origin xyz="0 0 0" rpy="0 0 0" />
            <inertia ixx="0.0" ixy="0.0" ixz="0.0" iyy="0.0" iyz="0.0" izz="0.0"/>
        </inertial>
        <visual>
            <!--box origin wrt jRightBirken-->
            <origin xyz="0 0 0" rpy="0 0 0" />
            <geometry>
                <box size="0 0 0"/>
            </geometry>
            <material name="color"/>
        </visual>
    </link>


##############################################################################
# LEFT HIP
##############################################################################	
	<link name="LeftUpperLeg_f1">
        <inertial>
            <mass value="1e-5"/>
            <origin xyz="0 0 0" rpy="0 0 0" />
            <inertia ixx="0.0" ixy="0.0" ixz="0.0" iyy="0.0" iyz="0.0" izz="0.0"/>
        </inertial>
    </link>
	<link name="LeftUpperLeg_f2">
        <inertial>
            <mass value="1e-5"/>
            <origin xyz="0 0 0" rpy="0 0 0" />
            <inertia ixx="0.0" ixy="0.0" ixz="0.0" iyy="0.0" iyz="0.0" izz="0.0"/>
        </inertial>
    </link>
##############################################################################
# LEFT UPPERLEG
##############################################################################
    <link name="LeftUpperLeg">
        <inertial>
            <mass value="1e-5"/>
			<!--COM origin wrt jLeftHip-->
            <origin xyz="0 0 0" rpy="0 0 0" />
            <inertia ixx="0.0" ixy="0.0" ixz="0.0" iyy="0.0" iyz="0.0" izz="0.0"/>
        </inertial>

        <visual>
			<!--box origin wrt jLeftHip-->
            <origin xyz="0 0 0" rpy="0 0 0" />
            <geometry>
                <cylinder length="1" radius="1"/>
            </geometry>
            <material name="color"/>
        </visual>

        <collision>
			<!--box origin wrt jLeftHip-->
            <origin xyz="0 0 0" rpy="0 0 0" />
            <geometry>
                <cylinder length="1" radius="1"/>
            </geometry>
        </collision>
    </link>
##############################################################################
# LEFT KNEE
##############################################################################
	<link name="LeftLowerLeg_f1">
        <inertial>
            <mass value="1e-5"/>
            <origin xyz="0 0 0" rpy="0 0 0" />
            <inertia ixx="0.0" ixy="0.0" ixz="0.0" iyy="0.0" iyz="0.0" izz="0.0"/>
        </inertial>
    </link>
##############################################################################
# LEFT LOWERLEG
##############################################################################
	<link name="LeftLowerLeg">
        <inertial>
            <mass value="1e-5"/>
			<!--COM origin wrt jLeftKnee-->
            <origin xyz="0 0 0" rpy="0 0 0" />
            <inertia ixx="0.0" iyy="0.0" izz="0.0" ixy="0.0" ixz="0.0" iyz="0.0"/>
        </inertial>

        <visual>
			<!--box origin wrt jLeftKnee-->
            <origin xyz="0 0 0" rpy="0 0 0" />
            <geometry>
                <cylinder length="1" radius="1"/>
            </geometry>
            <material name="color"/>
        </visual>

        <collision>
			<!--box origin wrt jLeftKnee-->
            <origin xyz="0 0 0" rpy="0 0 0" />
            <geometry>
                <cylinder length="1" radius="1"/>
            </geometry>
        </collision>

    </link>
##############################################################################
# LEFT ANKLE
##############################################################################
	<link name="LeftFoot_f1">
        <inertial>
            <mass value="1e-5"/>
            <origin xyz="0 0 0" rpy="0 0 0" />
            <inertia ixx="0.0" ixy="0.0" ixz="0.0" iyy="0.0" iyz="0.0" izz="0.0"/>
        </inertial>
    </link>
	<link name="LeftFoot_f2">
        <inertial>
            <mass value="1e-5"/>
            <origin xyz="0 0 0" rpy="0 0 0" />
            <inertia ixx="0.0" ixy="0.0" ixz="0.0" iyy="0.0" iyz="0.0" izz="0.0"/>
        </inertial>
    </link>
##############################################################################
# LEFT FOOT
##############################################################################
    <link name="LeftFoot">
        <inertial>
            <mass value="1e-5"/>
			<!--COM origin wrt jLeftAnkle-->
            <origin xyz="0 0 0" rpy="0 0 0" />
            <inertia ixx="0.0" ixy="0.0" ixz="0.0" iyy="0.0" iyz="0.0" izz="0.0"/>
        </inertial>

        <visual>
			<!--box origin wrt jLeftAnkle-->
	   	 	<origin xyz="0 0 0" rpy="0 0 0" />
            <geometry>
                <box size="1 1 1"/>
            </geometry>
            <material name="color"/>
        </visual>

        <collision>
			<!--box origin wrt jLeftAnkle-->
		    <origin xyz="0 0 0" rpy="0 0 0" />
	            <geometry>
	                <box size="1 1 1"/>
	            </geometry>
        </collision>
    </link>
##############################################################################
# LEFT TOE
##############################################################################
    <link name="LeftToe">
        <inertial>
            <mass value="1e-5"/>
			<!--COM origin wrt jLeftBallFoot-->
            <origin xyz="0 0 0" rpy="0 0 0" />
            <inertia ixx="0.0" ixy="0.0" ixz="0.0" iyy="0.0" iyz="0.0" izz="0.0"/>
        </inertial>

        <visual>
			<!--box origin wrt jLeftBallFoot-->
            <origin xyz="0 0 0" rpy="0 0 0" />
            <geometry>
                <box size="1 1 1"/>
            </geometry>
            <material name="color"/>
        </visual>

        <collision>
			<!--box origin wrt jLeftBallFoot-->
            <origin xyz="0 0 0" rpy="0 0 0" />
	        <geometry>
                <box size="1 1 1"/>
	        </geometry>
        </collision>
    </link>
##############################################################################
# LEFT FTSENSOR
##############################################################################
    <link name="LeftFTSensor">
        <inertial>
            <mass value="1e-05"/>
            <origin xyz="0 0 0" rpy="0 0 0" />
            <inertia ixx="0.0" ixy="0.0" ixz="0.0" iyy="0.0" iyz="0.0" izz="0.0"/>
        </inertial>
        <visual>
            <!--box origin wrt jLeftBirken-->
            <origin xyz="0 0 0" rpy="0 0 0" />
            <geometry>
                <box size="0 0 0"/>
            </geometry>
            <material name="color"/>
        </visual>
    </link>


<!--JOINTS-->

##############################################################################
# PELVI - LOWERTRUNK
##############################################################################
	
	<joint name="jL5S1_rotx" type="revolute">
        <origin xyz="0 0 0" rpy="0 0 0"/>
        <parent link="Pelvis"/>
        <child link="LowerTrunk_f1"/>
        <dynamics damping="0.1" friction="0.0"/>
        <limit effort="30" velocity="1.0" lower="-0.610865" upper="0.610865" />
        <axis xyz="1 0 0" />
    </joint>
	<joint name="jL5S1_roty" type="revolute">
        <origin xyz="0 0 0" rpy="0 0 0"/>
        <parent link="LowerTrunk_f1"/>
        <child link="LowerTrunk"/>
        <dynamics damping="0.1" friction="0.0"/>
        <limit effort="30" velocity="1.0" lower="-0.523599" upper="1.309" />
        <axis xyz="0 1 0" />
    </joint>
##############################################################################
# LOWERTRUNK - UPPERTRUNK
##############################################################################

	<joint name="jT9T8_rotx" type="revolute">
        <origin xyz="0 0 0" rpy="0 0 0"/>
        <parent link="LowerTrunk"/>
        <child link="UpperTrunk_f1"/>
        <dynamics damping="0.1" friction="0.0"/>
        <limit effort="30" velocity="1.0" lower="-0.349066" upper="0.349066" />
        <axis xyz="1 0 0" />
    </joint>
	<joint name="jT9T8_roty" type="revolute">
        <origin xyz="0 0 0" rpy="0 0 0"/>
        <parent link="UpperTrunk_f1"/>
        <child link="UpperTrunk_f2"/>
        <dynamics damping="0.1" friction="0.0"/>
        <limit effort="30" velocity="1.0" lower="-0.261799" upper="0.698132" />
        <axis xyz="0 1 0" />
    </joint>
    <joint name="jT9T8_rotz" type="revolute">
        <origin xyz="0 0 0" rpy="0 0 0"/>
        <parent link="UpperTrunk_f2"/>
        <child link="UpperTrunk"/>
        <dynamics damping="0.1" friction="0.0"/>
        <limit effort="30" velocity="1.0" lower="-0.610865" upper="0.610865" />
        <axis xyz="0 0 1" />
    </joint>
##############################################################################
# UPPERTRUNK - RIGHTSHOULDER
##############################################################################
	<joint name="jC7RightShoulder_rotx" type="revolute">
        <origin xyz="0 0 0" rpy="0 0 0"/>
        <parent link="UpperTrunk"/>
        <child link="RightShoulder"/>
        <dynamics damping="0.1" friction="0.0"/>
        <limit effort="30" velocity="1.0" lower="-0.785398" upper="0.0872665" />
        <axis xyz="1 0 0" />
    </joint>
##############################################################################
# UPPERTRUNK - LEFTSHOULDER
##############################################################################
	<joint name="jC7LeftShoulder_rotx" type="revolute">
        <origin xyz="0 0 0" rpy="0 0 0"/>
        <parent link="UpperTrunk"/>
        <child link="LeftShoulder"/>
        <dynamics damping="0.1" friction="0.0"/>
        <limit effort="30" velocity="1.0" lower="-0.0872665" upper="0.785398" />
        <axis xyz="1 0 0" />
    </joint>
##############################################################################
# UPPERTRUNK - NECK
##############################################################################

	<joint name="jT1C7_rotx" type="revolute">
        <origin xyz="0 0 0" rpy="0 0 0"/>
        <parent link="UpperTrunk"/>
        <child link="Neck_f1"/>
        <dynamics damping="0.1" friction="0.0"/>
        <limit effort="30" velocity="1.0" lower="-0.610865" upper="0.610865" />
        <axis xyz="1 0 0" />
    </joint>
	<joint name="jT1C7_roty" type="revolute">
        <origin xyz="0 0 0" rpy="0 0 0"/>
        <parent link="Neck_f1"/>
        <child link="Neck_f2"/>
        <dynamics damping="0.1" friction="0.0"/>
        <limit effort="30" velocity="1.0" lower="-0.959931" upper="1.5708" />
        <axis xyz="0 1 0" />
    </joint>
    <joint name="jT1C7_rotz" type="revolute">
        <origin xyz="0 0 0" rpy="0 0 0"/>
        <parent link="Neck_f2"/>
        <child link="Neck"/>
        <dynamics damping="0.1" friction="0.0"/>
        <limit effort="30" velocity="1.0" lower="-1.22173" upper="1.22173" />
        <axis xyz="0 0 1" />
    </joint>
##############################################################################
# NECK - HEAD
##############################################################################  
	<joint name="jC1Head_rotx" type="revolute">
        <origin xyz="0 0 0" rpy="0 0 0"/>
        <parent link="Neck"/>
        <child link="Head_f1"/>
        <dynamics damping="0.1" friction="0.0"/>
        <limit effort="30" velocity="1.0" lower="-0.610865" upper="0.610865" />
        <axis xyz="1 0 0" />
    </joint>
	<joint name="jC1Head_roty" type="revolute">
        <origin xyz="0 0 0" rpy="0 0 0"/>
        <parent link="Head_f1"/>
        <child link="Head"/>
        <dynamics damping="0.1" friction="0.0"/>
        <limit effort="30" velocity="1.0" lower="-0.436332" upper="0.174533" />
        <axis xyz="0 1 0" />
    </joint>


##############################################################################
# RIGHT SHOULDER
##############################################################################
	<joint name="jRightShoulder_rotx" type="revolute">
        <origin xyz="0 0 0" rpy="0 0 0"/>
        <parent link="RightShoulder"/>
        <child link="RightShoulder_f1"/>
        <dynamics damping="0.1" friction="0.0"/>
        <limit effort="30" velocity="1.0" lower="-0.8727" upper="0.8727" />
        <axis xyz="1 0 0" />
    </joint>
	<joint name="jRightShoulder_roty" type="revolute">
        <origin xyz="0 0 0" rpy="0 0 0"/>
        <parent link="RightShoulder_f1"/>
        <child link="RightShoulder_f2"/>
        <dynamics damping="0.1" friction="0.0"/>
        <limit effort="30" velocity="1.0" lower="-0.8727" upper="0.8727" />
        <axis xyz="0 1 0" />
    </joint>
    <joint name="jRightShoulder_rotz" type="revolute">
        <origin xyz="0 0 0" rpy="0 0 0"/>
        <parent link="RightShoulder_f2"/>
        <child link="RightUpperArm"/>
        <dynamics damping="0.1" friction="0.0"/>
        <limit effort="30" velocity="1.0" lower="-0.8727" upper="0.8727" />
        <axis xyz="0 0 1" />
    </joint>
##############################################################################
# RIGHT ELBOW
##############################################################################
	<joint name="jRightElbow_roty" type="revolute">
        <origin xyz="0 0 0" rpy="0 0 0"/>
        <parent link="RightUpperArm"/>
        <child link="RightForeArm_f1"/>
        <dynamics damping="0.1" friction="0.0"/>
        <limit effort="30" velocity="1.0" lower="-1.5708" upper="1.48353" />
        <axis xyz="0 1 0" />
    </joint>
    <joint name="jRightElbow_rotz" type="revolute">
        <origin xyz="0 0 0" rpy="0 0 0"/>
        <parent link="RightForeArm_f1"/>
        <child link="RightForeArm"/>
        <dynamics damping="0.1" friction="0.0"/>
        <limit effort="30" velocity="1.0" lower="0" upper="2.53073" />
        <axis xyz="0 0 1" />
    </joint>
##############################################################################
# RIGHT WRIST
##############################################################################
	<joint name="jRightWrist_rotx" type="revolute">
        <origin xyz="0 0 0" rpy="0 0 0"/>
        <parent link="RightForeArm"/>
        <child link="RightHand_f1"/>
        <dynamics damping="0.1" friction="0.0"/>
        <limit effort="30" velocity="1.0" lower="-0.872665" upper="1.0472" />
        <axis xyz="1 0 0" />
    </joint>
    <joint name="jRightWrist_rotz" type="revolute">
        <origin xyz="0 0 0" rpy="0 0 0"/>
        <parent link="RightHand_f1"/>
        <child link="RightHand"/>
        <dynamics damping="0.1" friction="0.0"/>
        <limit effort="30" velocity="1.0" lower="-0.523599" upper="0.349066" />
        <axis xyz="0 0 1" />
    </joint>
##############################################################################
# RIGHT HAND COM
##############################################################################   
    <joint name="jRightHandCOM" type="fixed">
        <origin xyz="0 0 0" rpy="0 0 0"/>
        <parent link="RightHand"/>
        <child link="RightHandCOM"/>
        <axis xyz="0 0 0" />
    </joint>


##############################################################################
# LEFT SHOULDER
##############################################################################

	<joint name="jLeftShoulder_rotx" type="revolute">
        <origin xyz="0 0 0" rpy="0 0 0"/>
        <parent link="LeftShoulder"/>
        <child link="LeftShoulder_f1"/>
        <dynamics damping="0.1" friction="0.0"/>
        <limit effort="30" velocity="1.0" lower="-0.8727" upper="0.8727" />
        <axis xyz="1 0 0" />
    </joint>
	<joint name="jLeftShoulder_roty" type="revolute">
        <origin xyz="0 0 0" rpy="0 0 0"/>
        <parent link="LeftShoulder_f1"/>
        <child link="LeftShoulder_f2"/>
        <dynamics damping="0.1" friction="0.0"/>
        <limit effort="30" velocity="1.0" lower="-0.8727" upper="0.8727" />
        <axis xyz="0 1 0" />
    </joint>
    <joint name="jLeftShoulder_rotz" type="revolute">
        <origin xyz="0 0 0" rpy="0 0 0"/>
        <parent link="LeftShoulder_f2"/>
        <child link="LeftUpperArm"/>
        <dynamics damping="0.1" friction="0.0"/>
        <limit effort="30" velocity="1.0" lower="-0.8727" upper="0.8727" />
        <axis xyz="0 0 1" />
    </joint>
##############################################################################
# LEFT ELBOW
##############################################################################
	<joint name="jLeftElbow_roty" type="revolute">
        <origin xyz="0 0 0" rpy="0 0 0"/>
        <parent link="LeftUpperArm"/>
        <child link="LeftForeArm_f1"/>
        <dynamics damping="0.1" friction="0.0"/>
        <limit effort="30" velocity="1.0" lower="-1.5708" upper="1.48353" />
        <axis xyz="0 1 0" />
    </joint>
    <joint name="jLeftElbow_rotz" type="revolute">
        <origin xyz="0 0 0" rpy="0 0 0"/>
        <parent link="LeftForeArm_f1"/>
        <child link="LeftForeArm"/>
        <dynamics damping="0.1" friction="0.0"/>
        <limit effort="30" velocity="1.0" lower="-2.53073" upper="0" />
        <axis xyz="0 0 1" />
    </joint>
##############################################################################
# LEFT WRIST
##############################################################################
	<joint name="jLeftWrist_rotx" type="revolute">
        <origin xyz="0 0 0" rpy="0 0 0"/>
        <parent link="LeftForeArm"/>
        <child link="LeftHand_f1"/>
        <dynamics damping="0.1" friction="0.0"/>
        <limit effort="30" velocity="1.0" lower="-1.0472" upper="0.872665" />
        <axis xyz="1 0 0" />
    </joint>
    <joint name="jLeftWrist_rotz" type="revolute">
        <origin xyz="0 0 0" rpy="0 0 0"/>
        <parent link="LeftHand_f1"/>
        <child link="LeftHand"/>
        <dynamics damping="0.1" friction="0.0"/>
        <limit effort="30" velocity="1.0" lower="-0.349066" upper="0.523599" />
        <axis xyz="0 0 1" />
    </joint>
##############################################################################
# LEFT HAND COM
############################################################################## 
    <joint name="jLeftHandCOM" type="fixed">
        <origin xyz="0 0 0" rpy="0 0 0"/>
        <parent link="LeftHand"/>
        <child link="LeftHandCOM"/>
        <axis xyz="0 0 0" />
    </joint>


##############################################################################
# RIGHT HIP
##############################################################################

	<joint name="jRightHip_rotx" type="revolute">
        <origin xyz="0 0 0" rpy="0 0 0"/>
        <parent link="Pelvis"/>
        <child link="RightUpperLeg_f1"/>
        <dynamics damping="0.1" friction="0.0"/>
        <limit effort="30" velocity="1.0" lower="-0.785398" upper="0.523599" />
        <axis xyz="1 0 0" />
    </joint>
	<joint name="jRightHip_roty" type="revolute">
        <origin xyz="0 0 0" rpy="0 0 0"/>
        <parent link="RightUpperLeg_f1"/>
        <child link="RightUpperLeg_f2"/>
        <dynamics damping="0.1" friction="0.0"/>
        <limit effort="30" velocity="1.0" lower="-2.0944" upper="0.261799" />
        <axis xyz="0 1 0" />
    </joint>
    <joint name="jRightHip_rotz" type="revolute">
        <origin xyz="0 0 0" rpy="0 0 0"/>
        <parent link="RightUpperLeg_f2"/>
        <child link="RightUpperLeg"/>
        <dynamics damping="0.1" friction="0.0"/>
        <limit effort="30" velocity="1.0" lower="-0.785398" upper="0.785398" />
        <axis xyz="0 0 1" />
    </joint>
##############################################################################
# RIGHT KNEE
##############################################################################
	<joint name="jRightKnee_roty" type="revolute">
        <origin xyz="0 0 0" rpy="0 0 0"/>
        <parent link="RightUpperLeg"/>
        <child link="RightLowerLeg_f1"/>
        <dynamics damping="0.1" friction="0.0"/>
        <limit effort="30" velocity="1.0" lower="0" upper="2.35619" />
        <axis xyz="0 1 0" />
    </joint>
    <joint name="jRightKnee_rotz" type="revolute">
        <origin xyz="0 0 0" rpy="0 0 0"/>
        <parent link="RightLowerLeg_f1"/>
        <child link="RightLowerLeg"/>
        <dynamics damping="0.1" friction="0.0"/>
        <limit effort="30" velocity="1.0" lower="-0.698132" upper="0.523599" />
        <axis xyz="0 0 1" />
    </joint>
##############################################################################
# RIGHT ANKLE
##############################################################################
	<joint name="jRightAnkle_rotx" type="revolute">
        <origin xyz="0 0 0" rpy="0 0 0"/>
        <parent link="RightLowerLeg"/>
        <child link="RightFoot_f1"/>
        <dynamics damping="0.1" friction="0.0"/>
        <limit effort="30" velocity="1.0" lower="-0.610865" upper="0.785398" />
        <axis xyz="1 0 0" />
    </joint>
	<joint name="jRightAnkle_roty" type="revolute">
        <origin xyz="0 0 0" rpy="0 0 0"/>
        <parent link="RightFoot_f1"/>
        <child link="RightFoot_f2"/>
        <dynamics damping="0.1" friction="0.0"/>
        <limit effort="30" velocity="1.0" lower="-0.523599" upper="0.872665" />
        <axis xyz="0 1 0" />
    </joint>
    <joint name="jRightAnkle_rotz" type="revolute">
        <origin xyz="0 0 0" rpy="0 0 0"/>
        <parent link="RightFoot_f2"/>
        <child link="RightFoot"/>
        <dynamics damping="0.1" friction="0.0"/>
        <limit effort="30" velocity="1.0" lower="-0.436332" upper="0.872665" />
        <axis xyz="0 0 1" />
    </joint>
##############################################################################
# RIGHT TOE
##############################################################################   
    <joint name="jRightBallFoot_roty" type="revolute">
        <origin xyz="0 0 0" rpy="0 0 0"/>
        <parent link="RightFoot"/>
        <child link="RightToe"/>
        <dynamics damping="0.1" friction="0.0"/>
        <limit effort="30" velocity="1.0" lower="-0.174533" upper="1.5708" />
        <axis xyz="0 1 0" />
    </joint>
##############################################################################
# RIGHT BIRKEN
##############################################################################   
    <joint name="jRightBirken_roty" type="fixed">
        <origin xyz="0 0 0" rpy="0 0 0"/>
        <parent link="RightFoot"/>
        <child link="RightFTSensor"/>
        <dynamics damping="0.1" friction="0.0"/>
        <limit effort="30" velocity="1.0" lower="-0.174533" upper="1.5708" />
        <axis xyz="0 1 0" />
    </joint>


##############################################################################
# LEFT HIP
##############################################################################

	<joint name="jLeftHip_rotx" type="revolute">
        <origin xyz="0 0 0" rpy="0 0 0"/>
        <parent link="Pelvis"/>
        <child link="LeftUpperLeg_f1"/>
        <dynamics damping="0.1" friction="0.0"/>
        <limit effort="30" velocity="1.0" lower="-0.523599" upper="0.785398" />
        <axis xyz="1 0 0" />
    </joint>
	<joint name="jLeftHip_roty" type="revolute">
        <origin xyz="0 0 0" rpy="0 0 0"/>
        <parent link="LeftUpperLeg_f1"/>
        <child link="LeftUpperLeg_f2"/>
        <dynamics damping="0.1" friction="0.0"/>
        <limit effort="30" velocity="1.0" lower="-2.0944" upper="0.261799" />
        <axis xyz="0 1 0" />
    </joint>
    <joint name="jLeftHip_rotz" type="revolute">
        <origin xyz="0 0 0" rpy="0 0 0"/>
        <parent link="LeftUpperLeg_f2"/>
        <child link="LeftUpperLeg"/>
        <dynamics damping="0.1" friction="0.0"/>
        <limit effort="30" velocity="1.0" lower="-0.785398" upper="0.785398" />
        <axis xyz="0 0 1" />
    </joint>
##############################################################################
# LEFT KNEE
##############################################################################
	<joint name="jLeftKnee_roty" type="revolute">
        <origin xyz="0 0 0" rpy="0 0 0"/>
        <parent link="LeftUpperLeg"/>
        <child link="LeftLowerLeg_f1"/>
        <dynamics damping="0.1" friction="0.0"/>
        <limit effort="30" velocity="1.0" lower="0" upper="2.35619" />
        <axis xyz="0 1 0" />
    </joint>
    <joint name="jLeftKnee_rotz" type="revolute">
        <origin xyz="0 0 0" rpy="0 0 0"/>
        <parent link="LeftLowerLeg_f1"/>
        <child link="LeftLowerLeg"/>
        <dynamics damping="0.1" friction="0.0"/>
        <limit effort="30" velocity="1.0" lower="-0.523599" upper="0.698132" />
        <axis xyz="0 0 1" />
    </joint>
##############################################################################
# LEFT ANKLE
##############################################################################
	<joint name="jLeftAnkle_rotx" type="revolute">
        <origin xyz="0 0 0"  rpy="0 0 0"/>
        <parent link="LeftLowerLeg"/>
        <child link="LeftFoot_f1"/>
        <dynamics damping="0.1" friction="0.0"/>
        <limit effort="30" velocity="1.0" lower="-0.785398" upper="0.610865" />
        <axis xyz="1 0 0" />
    </joint>
	<joint name="jLeftAnkle_roty" type="revolute">
        <origin xyz="0 0 0" rpy="0 0 0"/>
        <parent link="LeftFoot_f1"/>
        <child link="LeftFoot_f2"/>
        <dynamics damping="0.1" friction="0.0"/>
        <limit effort="30" velocity="1.0" lower="-0.523599" upper="0.872665" />
        <axis xyz="0 1 0" />
    </joint>
    <joint name="jLeftAnkle_rotz" type="revolute">
        <origin xyz="0 0 0" rpy="0 0 0"/>
        <parent link="LeftFoot_f2"/>
        <child link="LeftFoot"/>
        <dynamics damping="0.1" friction="0.0"/>
        <limit effort="30" velocity="1.0" lower="-0.872665" upper="0.436332" />
        <axis xyz="0 0 1" />
    </joint>
##############################################################################
# LEFT TOE
##############################################################################   
    <joint name="jLeftBallFoot_roty" type="revolute">
        <origin xyz="0 0 0" rpy="0 0 0"/>
        <parent link="LeftFoot"/>
        <child link="LeftToe"/>
        <dynamics damping="0.1" friction="0.0"/>
        <limit effort="30" velocity="1.0" lower="-0.174533" upper="1.5708" />
        <axis xyz="0 1 0" />
    </joint>
##############################################################################
# LEFT BIRKEN
##############################################################################   
    <joint name="jLeftBirken_roty" type="fixed">
        <origin xyz="0 0 0" rpy="0 0 0"/>
        <parent link="LeftFoot"/>
        <child link="LeftFTSensor"/>
        <dynamics damping="0.1" friction="0.0"/>
        <limit effort="30" velocity="1.0" lower="-0.174533" upper="1.5708" />
        <axis xyz="0 1 0" />
    </joint>


<!--MUSCLE LINKS-->  



##############################################################################
# RIGHT BICBRAC ORIGIN
##############################################################################
    <link name="BicBrac_RUA">
        <inertial>
            <mass value="0.0"/>
            <origin xyz="0 0 0" rpy="0 0 0" />
            <inertia ixx="0.0" ixy="0.0" ixz="0.0" iyy="0.0" iyz="0.0" izz="0.0"/>
        </inertial>
    </link>
##############################################################################
# RIGHT BICBRAC INSERTION
##############################################################################
    <link name="BicBrac_RFA">
        <inertial>
            <mass value="0.0"/>
            <origin xyz="0 0 0" rpy="0 0 0" />
            <inertia ixx="0.0" ixy="0.0" ixz="0.0" iyy="0.0" iyz="0.0" izz="0.0"/>
        </inertial>
    </link>
##############################################################################
# RIGHT TRICBRAC ORIGIN
##############################################################################
    <link name="TricBrac_RUA">
        <inertial>
            <mass value="0.0"/>
            <origin xyz="0 0 0" rpy="0 0 0" />
            <inertia ixx="0.0" ixy="0.0" ixz="0.0" iyy="0.0" iyz="0.0" izz="0.0"/>
        </inertial>
    </link>
##############################################################################
# RIGHT TRICBRAC INSERTION
##############################################################################
    <link name="TricBrac_RFA">
        <inertial>
            <mass value="0.0"/>
            <origin xyz="0 0 0" rpy="0 0 0" />
            <inertia ixx="0.0" ixy="0.0" ixz="0.0" iyy="0.0" iyz="0.0" izz="0.0"/>
        </inertial>
    </link>
##############################################################################
# RIGHT FLEXCARP ORIGIN
##############################################################################
    <link name="FlexCarp_RFA">
        <inertial>
            <mass value="0.0"/>
            <origin xyz="0 0 0" rpy="0 0 0" />
            <inertia ixx="0.0" ixy="0.0" ixz="0.0" iyy="0.0" iyz="0.0" izz="0.0"/>
        </inertial>
    </link>
##############################################################################
# RIGHT FLEXCARP INSERTION
##############################################################################
    <link name="FlexCarp_RH">
        <inertial>
            <mass value="0.0"/>
            <origin xyz="0 0 0" rpy="0 0 0" />
            <inertia ixx="0.0" ixy="0.0" ixz="0.0" iyy="0.0" iyz="0.0" izz="0.0"/>
        </inertial>
    </link>
##############################################################################
# RIGHT EXTCARP ORIGIN
##############################################################################
    <link name="ExtCarp_RFA">
        <inertial>
            <mass value="0.0"/>
            <origin xyz="0 0 0" rpy="0 0 0" />
            <inertia ixx="0.0" ixy="0.0" ixz="0.0" iyy="0.0" iyz="0.0" izz="0.0"/>
        </inertial>
    </link>
##############################################################################
# RIGHT EXTCARP INSERTION
##############################################################################
    <link name="ExtCarp_RH">
        <inertial>
            <mass value="0.0"/>
            <origin xyz="0 0 0" rpy="0 0 0" />
            <inertia ixx="0.0" ixy="0.0" ixz="0.0" iyy="0.0" iyz="0.0" izz="0.0"/>
        </inertial>
    </link>


##############################################################################
# LEFT BICBRAC ORIGIN
##############################################################################
    <link name="BicBrac_LUA">
        <inertial>
            <mass value="0.0"/>
            <origin xyz="0 0 0" rpy="0 0 0" />
            <inertia ixx="0.0" ixy="0.0" ixz="0.0" iyy="0.0" iyz="0.0" izz="0.0"/>
        </inertial>
    </link>
##############################################################################
# LEFT BICBRAC INSERTION
##############################################################################
    <link name="BicBrac_LFA">
        <inertial>
            <mass value="0.0"/>
            <origin xyz="0 0 0" rpy="0 0 0" />
            <inertia ixx="0.0" ixy="0.0" ixz="0.0" iyy="0.0" iyz="0.0" izz="0.0"/>
        </inertial>
    </link>
##############################################################################
# LEFT TRICBRAC ORIGIN
##############################################################################
    <link name="TricBrac_LUA">
        <inertial>
            <mass value="0.0"/>
            <origin xyz="0 0 0" rpy="0 0 0" />
            <inertia ixx="0.0" ixy="0.0" ixz="0.0" iyy="0.0" iyz="0.0" izz="0.0"/>
        </inertial>
    </link>
##############################################################################
# LEFT TRICBRAC INSERTION
##############################################################################
    <link name="TricBrac_LFA">
        <inertial>
            <mass value="0.0"/>
            <origin xyz="0 0 0" rpy="0 0 0" />
            <inertia ixx="0.0" ixy="0.0" ixz="0.0" iyy="0.0" iyz="0.0" izz="0.0"/>
        </inertial>
    </link>
##############################################################################
# LEFT FLEXCARP ORIGIN
##############################################################################
    <link name="FlexCarp_LFA">
        <inertial>
            <mass value="0.0"/>
            <origin xyz="0 0 0" rpy="0 0 0" />
            <inertia ixx="0.0" ixy="0.0" ixz="0.0" iyy="0.0" iyz="0.0" izz="0.0"/>
        </inertial>
    </link>
##############################################################################
# LEFT FLEXCARP INSERTION
##############################################################################
    <link name="FlexCarp_LH">
        <inertial>
            <mass value="0.0"/>
            <origin xyz="0 0 0" rpy="0 0 0" />
            <inertia ixx="0.0" ixy="0.0" ixz="0.0" iyy="0.0" iyz="0.0" izz="0.0"/>
        </inertial>
    </link>
##############################################################################
# LEFT EXTCARP ORIGIN
##############################################################################
    <link name="ExtCarp_LFA">
        <inertial>
            <mass value="0.0"/>
            <origin xyz="0 0 0" rpy="0 0 0" />
            <inertia ixx="0.0" ixy="0.0" ixz="0.0" iyy="0.0" iyz="0.0" izz="0.0"/>
        </inertial>
    </link>
##############################################################################
# LEFT EXTCARP INSERTION
##############################################################################
    <link name="ExtCarp_LH">
        <inertial>
            <mass value="0.0"/>
            <origin xyz="0 0 0" rpy="0 0 0" />
            <inertia ixx="0.0" ixy="0.0" ixz="0.0" iyy="0.0" iyz="0.0" izz="0.0"/>
        </inertial>
    </link>


##############################################################################
# RIGHT RECABD ORIGIN
##############################################################################
    <link name="RecAbd_RUT">
        <inertial>
            <mass value="0.0"/>
            <origin xyz="0 0 0" rpy="0 0 0" />
            <inertia ixx="0.0" ixy="0.0" ixz="0.0" iyy="0.0" iyz="0.0" izz="0.0"/>
        </inertial>
    </link>
##############################################################################
# RIGHT RECABD INSERTION
##############################################################################
    <link name="RecAbd_RP">
        <inertial>
            <mass value="0.0"/>
            <origin xyz="0 0 0" rpy="0 0 0" />
            <inertia ixx="0.0" ixy="0.0" ixz="0.0" iyy="0.0" iyz="0.0" izz="0.0"/>
        </inertial>
    </link>
##############################################################################
 RIGHT ERSPIN ORIGIN
##############################################################################
    <link name="ErSpin_RUT">
        <inertial>
            <mass value="0.0"/>
            <origin xyz="0 0 0" rpy="0 0 0" />
            <inertia ixx="0.0" ixy="0.0" ixz="0.0" iyy="0.0" iyz="0.0" izz="0.0"/>
        </inertial>
    </link>
##############################################################################
# RIGHT ERSPIN INSERTION
##############################################################################
    <link name="ErSpin_RP">
        <inertial>
            <mass value="0.0"/>
            <origin xyz="0 0 0" rpy="0 0 0" />
            <inertia ixx="0.0" ixy="0.0" ixz="0.0" iyy="0.0" iyz="0.0" izz="0.0"/>
        </inertial>
    </link>


##############################################################################
 LEFT RECABD ORIGIN
##############################################################################
    <link name="RecAbd_LUT">
        <inertial>
            <mass value="0.0"/>
            <origin xyz="0 0 0" rpy="0 0 0" />
            <inertia ixx="0.0" ixy="0.0" ixz="0.0" iyy="0.0" iyz="0.0" izz="0.0"/>
        </inertial>
    </link>
##############################################################################
# LEFT RECABD INSERTION
##############################################################################
    <link name="RecAbd_LP">
        <inertial>
            <mass value="0.0"/>
            <origin xyz="0 0 0" rpy="0 0 0" />
            <inertia ixx="0.0" ixy="0.0" ixz="0.0" iyy="0.0" iyz="0.0" izz="0.0"/>
        </inertial>
    </link>
##############################################################################
 LEFT ERSPIN ORIGIN
##############################################################################
    <link name="ErSpin_LUT">
        <inertial>
            <mass value="0.0"/>
            <origin xyz="0 0 0" rpy="0 0 0" />
            <inertia ixx="0.0" ixy="0.0" ixz="0.0" iyy="0.0" iyz="0.0" izz="0.0"/>
        </inertial>
    </link>
##############################################################################
# LEFT ERSPIN INSERTION
##############################################################################
    <link name="ErSpin_LP">
        <inertial>
            <mass value="0.0"/>
            <origin xyz="0 0 0" rpy="0 0 0" />
            <inertia ixx="0.0" ixy="0.0" ixz="0.0" iyy="0.0" iyz="0.0" izz="0.0"/>
        </inertial>
    </link>


##############################################################################
# RIGHT RECFEM ORIGIN
##############################################################################
    <link name="RecFem_RLT">
        <inertial>
            <mass value="0.0"/>
            <origin xyz="0 0 0" rpy="0 0 0" />
            <inertia ixx="0.0" ixy="0.0" ixz="0.0" iyy="0.0" iyz="0.0" izz="0.0"/>
        </inertial>
    </link>
##############################################################################
# RIGHT RECFEM INSERTION
##############################################################################
    <link name="RecFem_RLL">
        <inertial>
            <mass value="0.0"/>
            <origin xyz="0 0 0" rpy="0 0 0" />
            <inertia ixx="0.0" ixy="0.0" ixz="0.0" iyy="0.0" iyz="0.0" izz="0.0"/>
        </inertial>
    </link>
##############################################################################
# RIGHT BICFEM ORIGIN
##############################################################################
    <link name="BicFem_RUL">
        <inertial>
            <mass value="0.0"/>
            <origin xyz="0 0 0" rpy="0 0 0" />
            <inertia ixx="0.0" ixy="0.0" ixz="0.0" iyy="0.0" iyz="0.0" izz="0.0"/>
        </inertial>
    </link>
##############################################################################
# RIGHT BICFEM INSERTION
##############################################################################
    <link name="BicFem_RLL">
        <inertial>
            <mass value="0.0"/>
            <origin xyz="0 0 0" rpy="0 0 0" />
            <inertia ixx="0.0" ixy="0.0" ixz="0.0" iyy="0.0" iyz="0.0" izz="0.0"/>
        </inertial>
    </link>


##############################################################################
# LEFT RECFEM ORIGIN
##############################################################################
    <link name="RecFem_LLT">
        <inertial>
            <mass value="0.0"/>
            <origin xyz="0 0 0" rpy="0 0 0" />
            <inertia ixx="0.0" ixy="0.0" ixz="0.0" iyy="0.0" iyz="0.0" izz="0.0"/>
        </inertial>
    </link>
##############################################################################
# LEFT RECFEM INSERTION
##############################################################################
    <link name="RecFem_LLL">
        <inertial>
            <mass value="0.0"/>
            <origin xyz="0 0 0" rpy="0 0 0" />
            <inertia ixx="0.0" ixy="0.0" ixz="0.0" iyy="0.0" iyz="0.0" izz="0.0"/>
        </inertial>
    </link>
##############################################################################
# LEFT BICFEM ORIGIN
##############################################################################
    <link name="BicFem_LUL">
        <inertial>
            <mass value="0.0"/>
            <origin xyz="0 0 0" rpy="0 0 0" />
            <inertia ixx="0.0" ixy="0.0" ixz="0.0" iyy="0.0" iyz="0.0" izz="0.0"/>
        </inertial>
    </link>
##############################################################################
# LEFT BICFEM INSERTION
##############################################################################
    <link name="BicFem_LLL">
        <inertial>
            <mass value="0.0"/>
            <origin xyz="0 0 0" rpy="0 0 0" />
            <inertia ixx="0.0" ixy="0.0" ixz="0.0" iyy="0.0" iyz="0.0" izz="0.0"/>
        </inertial>
    </link>


##############################################################################
# RIGHT TIBANT ORIGIN
##############################################################################
    <link name="TibAnt_RLL">
        <inertial>
            <mass value="0.0"/>
            <origin xyz="0 0 0" rpy="0 0 0" />
            <inertia ixx="0.0" ixy="0.0" ixz="0.0" iyy="0.0" iyz="0.0" izz="0.0"/>
        </inertial>
    </link>
##############################################################################
# RIGHT TIBANT INSERTION
##############################################################################
    <link name="TibAnt_RF">
        <inertial>
            <mass value="0.0"/>
            <origin xyz="0 0 0" rpy="0 0 0" />
            <inertia ixx="0.0" ixy="0.0" ixz="0.0" iyy="0.0" iyz="0.0" izz="0.0"/>
        </inertial>
    </link>
##############################################################################
# RIGHT GASLAT ORIGIN
##############################################################################
    <link name="GasLat_RUL">
        <inertial>
            <mass value="0.0"/>
            <origin xyz="0 0 0" rpy="0 0 0" />
            <inertia ixx="0.0" ixy="0.0" ixz="0.0" iyy="0.0" iyz="0.0" izz="0.0"/>
        </inertial>
    </link>
##############################################################################
# RIGHT GASLAT INSERTION
##############################################################################
    <link name="GasLat_RF">
        <inertial>
            <mass value="0.0"/>
            <origin xyz="0 0 0" rpy="0 0 0" />
            <inertia ixx="0.0" ixy="0.0" ixz="0.0" iyy="0.0" iyz="0.0" izz="0.0"/>
        </inertial>
    </link>
##############################################################################
# RIGHT GASMED ORIGIN
##############################################################################
    <link name="GasMed_RUL">
        <inertial>
            <mass value="0.0"/>
            <origin xyz="0 0 0" rpy="0 0 0" />
            <inertia ixx="0.0" ixy="0.0" ixz="0.0" iyy="0.0" iyz="0.0" izz="0.0"/>
        </inertial>
    </link>
##############################################################################
# RIGHT GASMED INSERTION
##############################################################################
    <link name="GasMed_RF">
        <inertial>
            <mass value="0.0"/>
            <origin xyz="0 0 0" rpy="0 0 0" />
            <inertia ixx="0.0" ixy="0.0" ixz="0.0" iyy="0.0" iyz="0.0" izz="0.0"/>
        </inertial>
    </link>


##############################################################################
# LEFT TIBANT ORIGIN
##############################################################################
    <link name="TibAnt_LLL">
        <inertial>
            <mass value="0.0"/>
            <origin xyz="0 0 0" rpy="0 0 0" />
            <inertia ixx="0.0" ixy="0.0" ixz="0.0" iyy="0.0" iyz="0.0" izz="0.0"/>
        </inertial>
    </link>
##############################################################################
# LEFT TIBANT INSERTION
##############################################################################
    <link name="TibAnt_LF">
        <inertial>
            <mass value="0.0"/>
            <origin xyz="0 0 0" rpy="0 0 0" />
            <inertia ixx="0.0" ixy="0.0" ixz="0.0" iyy="0.0" iyz="0.0" izz="0.0"/>
        </inertial>
    </link>
##############################################################################
# LEFT GASLAT ORIGIN
##############################################################################
    <link name="GasLat_LUL">
        <inertial>
            <mass value="0.0"/>
            <origin xyz="0 0 0" rpy="0 0 0" />
            <inertia ixx="0.0" ixy="0.0" ixz="0.0" iyy="0.0" iyz="0.0" izz="0.0"/>
        </inertial>
    </link>
##############################################################################
# LEFT GASLAT INSERTION
##############################################################################
    <link name="GasLat_LF">
        <inertial>
            <mass value="0.0"/>
            <origin xyz="0 0 0" rpy="0 0 0" />
            <inertia ixx="0.0" ixy="0.0" ixz="0.0" iyy="0.0" iyz="0.0" izz="0.0"/>
        </inertial>
    </link>
##############################################################################
# LEFT GASMED ORIGIN
##############################################################################
    <link name="GasMed_LUL">
        <inertial>
            <mass value="0.0"/>
            <origin xyz="0 0 0" rpy="0 0 0" />
            <inertia ixx="0.0" ixy="0.0" ixz="0.0" iyy="0.0" iyz="0.0" izz="0.0"/>
        </inertial>
    </link>
##############################################################################
# LEFT GASMED INSERTION
##############################################################################
    <link name="GasMed_LF">
        <inertial>
            <mass value="0.0"/>
            <origin xyz="0 0 0" rpy="0 0 0" />
            <inertia ixx="0.0" ixy="0.0" ixz="0.0" iyy="0.0" iyz="0.0" izz="0.0"/>
        </inertial>
    </link>



<!--MUSCLE JOINT-->  


##############################################################################
# RIGHT BICBRAC ORIGIN
##############################################################################
    <joint name="jRightBicBrac_RUA" type="fixed">
        <origin xyz="0 0 0" rpy="0 0 0"/>
        <parent link="RightUpperArm"/>
        <child link="BicBrac_RUA"/>
        <axis xyz="0 0 0" />
    </joint>
##############################################################################
# RIGHT BICBRAC INSERTION
##############################################################################
    <joint name="jRightBicBrac_RFA" type="fixed">
        <origin xyz="0 0 0" rpy="0 0 0"/>
        <parent link="RightForeArm"/>
        <child link="BicBrac_RFA"/>
        <axis xyz="0 0 0" />
    </joint>
##############################################################################
# RIGHT TRICBRAC ORIGIN
##############################################################################
    <joint name="jRightTricBrac_RUA" type="fixed">
        <origin xyz="0 0 0" rpy="0 0 0"/>
        <parent link="RightUpperArm"/>
        <child link="TricBrac_RUA"/>
        <axis xyz="0 0 0" />
    </joint>
##############################################################################
# RIGHT TRICBRAC INSERTION
##############################################################################
    <joint name="jRightTricBrac_RFA" type="fixed">
        <origin xyz="0 0 0" rpy="0 0 0"/>
        <parent link="RightForeArm"/>
        <child link="TricBrac_RFA"/>
        <axis xyz="0 0 0" />
    </joint>
##############################################################################
# RIGHT FLEXCARP ORIGIN
##############################################################################
    <joint name="jRightFlexCarp_RFA" type="fixed">
        <origin xyz="0 0 0" rpy="0 0 0"/>
        <parent link="RightForeArm"/>
        <child link="FlexCarp_RFA"/>
        <axis xyz="0 0 0" />
    </joint>
##############################################################################
# RIGHT FLEXCARP INSERTION
##############################################################################
    <joint name="jRightFlexCarp_RH" type="fixed">
        <origin xyz="0 0 0" rpy="0 0 0"/>
        <parent link="RightHand"/>
        <child link="FlexCarp_RH"/>
        <axis xyz="0 0 0" />
    </joint>
##############################################################################
# RIGHT EXTCARP ORIGIN
##############################################################################
    <joint name="jRightExtCarp_RFA" type="fixed">
        <origin xyz="0 0 0" rpy="0 0 0"/>
        <parent link="RightForeArm"/>
        <child link="ExtCarp_RFA"/>
        <axis xyz="0 0 0" />
    </joint>
##############################################################################
# RIGHT EXTCARP INSERTION
##############################################################################
    <joint name="jRightExtCarp_RH" type="fixed">
        <origin xyz="0 0 0" rpy="0 0 0"/>
        <parent link="RightHand"/>
        <child link="ExtCarp_RH"/>
        <axis xyz="0 0 0" />
    </joint>


##############################################################################
# LEFT BICBRAC ORIGIN
##############################################################################
    <joint name="jLeftBicBrac_LUA" type="fixed">
        <origin xyz="0 0 0" rpy="0 0 0"/>
        <parent link="LeftUpperArm"/>
        <child link="BicBrac_LUA"/>
        <axis xyz="0 0 0" />
    </joint>
##############################################################################
# LEFT BICBRAC INSERTION
##############################################################################
    <joint name="jLeftBicBrac_LFA" type="fixed">
        <origin xyz="0 0 0" rpy="0 0 0"/>
        <parent link="LeftForeArm"/>
        <child link="BicBrac_LFA"/>
        <axis xyz="0 0 0" />
    </joint>
##############################################################################
# LEFT TRICBRAC ORIGIN
##############################################################################
    <joint name="jLeftTricBrac_LUA" type="fixed">
        <origin xyz="0 0 0" rpy="0 0 0"/>
        <parent link="LeftUpperArm"/>
        <child link="TricBrac_LUA"/>
        <axis xyz="0 0 0" />
    </joint>
##############################################################################
# LEFT TRICBRAC INSERTION
##############################################################################
    <joint name="jLeftTricBrac_LFA" type="fixed">
        <origin xyz="0 0 0" rpy="0 0 0"/>
        <parent link="LeftForeArm"/>
        <child link="TricBrac_LFA"/>
        <axis xyz="0 0 0" />
    </joint>
##############################################################################
# LEFT FLEXCARP ORIGIN
##############################################################################
    <joint name="jLeftFlexCarp_LFA" type="fixed">
        <origin xyz="0 0 0" rpy="0 0 0"/>
        <parent link="LeftForeArm"/>
        <child link="FlexCarp_LFA"/>
        <axis xyz="0 0 0" />
    </joint>
##############################################################################
# LEFT FLEXCARP INSERTION
##############################################################################
    <joint name="jLeftFlexCarp_LH" type="fixed">
        <origin xyz="0 0 0" rpy="0 0 0"/>
        <parent link="LeftHand"/>
        <child link="FlexCarp_LH"/>
        <axis xyz="0 0 0" />
    </joint>
##############################################################################
# LEFT EXTCARP ORIGIN
##############################################################################
    <joint name="jLeftExtCarp_LFA" type="fixed">
        <origin xyz="0 0 0" rpy="0 0 0"/>
        <parent link="LeftForeArm"/>
        <child link="ExtCarp_LFA"/>
        <axis xyz="0 0 0" />
    </joint>
##############################################################################
# LEFT EXTCARP INSERTION
##############################################################################
    <joint name="jLeftExtCarp_LH" type="fixed">
        <origin xyz="0 0 0" rpy="0 0 0"/>
        <parent link="LeftHand"/>
        <child link="ExtCarp_LH"/>
        <axis xyz="0 0 0" />
    </joint>


##############################################################################
# RIGHT RECABD ORIGIN
##############################################################################
    <joint name="jRightRecAbd_RUT" type="fixed">
        <origin xyz="0 0 0" rpy="0 0 0"/>
        <parent link="UpperTrunk"/>
        <child link="RecAbd_RUT"/>
        <axis xyz="0 0 0" />
    </joint>
##############################################################################
# RIGHT RECABD INSERTION
##############################################################################
    <joint name="jRightRecAbd_RP" type="fixed">
        <origin xyz="0 0 0" rpy="0 0 0"/>
        <parent link="Pelvis"/>
        <child link="RecAbd_RP"/>
        <axis xyz="0 0 0" />
    </joint>
##############################################################################
# RIGHT ERSPIN ORIGIN
##############################################################################
    <joint name="jRightErSpin_RUT" type="fixed">
        <origin xyz="0 0 0" rpy="0 0 0"/>
        <parent link="UpperTrunk"/>
        <child link="ErSpin_RUT"/>
        <axis xyz="0 0 0" />
    </joint>
##############################################################################
# RIGHT ERSPIN INSERTION
##############################################################################
    <joint name="jRightErSpin_RP" type="fixed">
        <origin xyz="0 0 0" rpy="0 0 0"/>
        <parent link="Pelvis"/>
        <child link="ErSpin_RP"/>
        <axis xyz="0 0 0" />
    </joint>


##############################################################################
# LEFT RECABD ORIGIN
##############################################################################
    <joint name="jLeftRecAbd_LUT" type="fixed">
        <origin xyz="0 0 0" rpy="0 0 0"/>
        <parent link="UpperTrunk"/>
        <child link="RecAbd_LUT"/>
        <axis xyz="0 0 0" />
    </joint>
##############################################################################
# LEFT RECABD INSERTION
##############################################################################
    <joint name="jLeftRecAbd_LP" type="fixed">
        <origin xyz="0 0 0" rpy="0 0 0"/>
        <parent link="Pelvis"/>
        <child link="RecAbd_LP"/>
        <axis xyz="0 0 0" />
    </joint>
##############################################################################
# LEFT ERSPIN ORIGIN
##############################################################################
    <joint name="jLeftErSpin_LUT" type="fixed">
        <origin xyz="0 0 0" rpy="0 0 0"/>
        <parent link="UpperTrunk"/>
        <child link="ErSpin_LUT"/>
        <axis xyz="0 0 0" />
    </joint>
##############################################################################
# LEFT ERSPIN INSERTION
##############################################################################
    <joint name="jLeftErSpin_LP" type="fixed">
        <origin xyz="0 0 0" rpy="0 0 0"/>
        <parent link="Pelvis"/>
        <child link="ErSpin_LP"/>
        <axis xyz="0 0 0" />
    </joint>


##############################################################################
# RIGHT RECFEM ORIGIN
##############################################################################
    <joint name="jRightRecFem_RP" type="fixed">
        <origin xyz="0 0 0" rpy="0 0 0"/>
        <parent link="Pelvis"/>
        <child link="RecFem_RLT"/>
        <axis xyz="0 0 0" />
    </joint>
##############################################################################
# RIGHT RECFEM INSERTION
##############################################################################
    <joint name="jRightRecFem_RLL" type="fixed">
        <origin xyz="0 0 0" rpy="0 0 0"/>
        <parent link="RightLowerLeg"/>
        <child link="RecFem_RLL"/>
        <axis xyz="0 0 0" />
    </joint>
##############################################################################
# RIGHT BICFEM ORIGIN
##############################################################################
    <joint name="jRightBicFem_RUL" type="fixed">
        <origin xyz="0 0 0" rpy="0 0 0"/>
        <parent link="RightUpperLeg"/>
        <child link="BicFem_RUL"/>
        <axis xyz="0 0 0" />
    </joint>
##############################################################################
# RIGHT BICFEM INSERTION
##############################################################################
    <joint name="jRightBicFem_RLL" type="fixed">
        <origin xyz="0 0 0" rpy="0 0 0"/>
        <parent link="RightLowerLeg"/>
        <child link="BicFem_RLL"/>
        <axis xyz="0 0 0" />
    </joint>


##############################################################################
# LEFT RECFEM ORIGIN
##############################################################################
    <joint name="jLeftRecFem_LP" type="fixed">
        <origin xyz="0 0 0" rpy="0 0 0"/>
        <parent link="Pelvis"/>
        <child link="RecFem_LLT"/>
        <axis xyz="0 0 0" />
    </joint>
##############################################################################
# LEFT RECFEM INSERTION
##############################################################################
    <joint name="jLeftRecFem_LLL" type="fixed">
        <origin xyz="0 0 0" rpy="0 0 0"/>
        <parent link="LeftLowerLeg"/>
        <child link="RecFem_LLL"/>
        <axis xyz="0 0 0" />
    </joint>
##############################################################################
# LEFT BICFEM ORIGIN
##############################################################################
    <joint name="jLeftBicFem_LUL" type="fixed">
        <origin xyz="0 0 0" rpy="0 0 0"/>
        <parent link="LeftUpperLeg"/>
        <child link="BicFem_LUL"/>
        <axis xyz="0 0 0" />
    </joint>
##############################################################################
# LEFT BICFEM INSERTION
##############################################################################
    <joint name="jLeftBicFem_LLL" type="fixed">
        <origin xyz="0 0 0" rpy="0 0 0"/>
        <parent link="LeftLowerLeg"/>
        <child link="BicFem_LLL"/>
        <axis xyz="0 0 0" />
    </joint>


############################################################################## 
# RIGHT TIBANT ORIGIN
##############################################################################
    <joint name="jRightTibAnt_RLL" type="fixed">
        <origin xyz="0 0 0" rpy="0 0 0"/>
        <parent link="RightLowerLeg"/>
        <child link="TibAnt_RLL"/>
        <axis xyz="0 0 0" />
    </joint>
##############################################################################
# RIGHT TIBANT INSERTION
##############################################################################
    <joint name="jRightTibAnt_RF" type="fixed">
        <origin xyz="0 0 0" rpy="0 0 0"/>
        <parent link="RightFoot"/>
        <child link="TibAnt_RF"/>
        <axis xyz="0 0 0" />
    </joint>
##############################################################################
# RIGHT GASLAT ORIGIN
##############################################################################
    <joint name="jRightGasLat_RUL" type="fixed">
        <origin xyz="0 0 0" rpy="0 0 0"/>
        <parent link="RightUpperLeg"/>
        <child link="GasLat_RUL"/>
        <axis xyz="0 0 0" />
    </joint>
##############################################################################
# RIGHT GASLAT INSERTION
##############################################################################
    <joint name="jRightGasLat_RF" type="fixed">
        <origin xyz="0 0 0" rpy="0 0 0"/>
        <parent link="RightFoot"/>
        <child link="GasLat_RF"/>
        <axis xyz="0 0 0" />
    </joint>
##############################################################################  
# RIGHT GASMED ORIGIN
##############################################################################
    <joint name="jRightGasMed_RUL" type="fixed">
        <origin xyz="0 0 0" rpy="0 0 0"/>
        <parent link="RightUpperLeg"/>
        <child link="GasMed_RUL"/>
        <axis xyz="0 0 0" />
    </joint>
##############################################################################
# RIGHT GASMED INSERTION
##############################################################################
    <joint name="jRightGasMed_RF" type="fixed">
        <origin xyz="0 0 0" rpy="0 0 0"/>
        <parent link="RightFoot"/>
        <child link="GasMed_RF"/>
        <axis xyz="0 0 0" />
    </joint>


##############################################################################
# LEFT TIBANT ORIGIN
##############################################################################
    <joint name="jLeftTibAnt_LLL" type="fixed">
        <origin xyz="0 0 0" rpy="0 0 0"/>
        <parent link="LeftLowerLeg"/>
        <child link="TibAnt_LLL"/>
        <axis xyz="0 0 0" />
    </joint>
############################################################################## 
# LEFT TIBANT INSERTION
##############################################################################
    <joint name="jLeftTibAnt_LF" type="fixed">
        <origin xyz="0 0 0" rpy="0 0 0"/>
        <parent link="LeftFoot"/>
        <child link="TibAnt_LF"/>
        <axis xyz="0 0 0" />
    </joint>
##############################################################################
# LEFT GASLAT ORIGIN
##############################################################################
    <joint name="jLeftGasLat_LUL" type="fixed">
        <origin xyz="0 0 0" rpy="0 0 0"/>
        <parent link="LeftUpperLeg"/>
        <child link="GasLat_LUL"/>
        <axis xyz="0 0 0" />
    </joint>
##############################################################################
# LEFT GASLAT INSERTION
##############################################################################
    <joint name="jLeftGasLat_LF" type="fixed">
        <origin xyz="0 0 0" rpy="0 0 0"/>
        <parent link="LeftFoot"/>
        <child link="GasLat_LF"/>
        <axis xyz="0 0 0" />
    </joint>
##############################################################################  
# LEFT GASMED ORIGIN
##############################################################################
    <joint name="jLeftGasMed_LUL" type="fixed">
        <origin xyz="0 0 0" rpy="0 0 0"/>
        <parent link="LeftUpperLeg"/>
        <child link="GasMed_LUL"/>
        <axis xyz="0 0 0" />
    </joint>
##############################################################################
# LEFT GASMED INSERTION
##############################################################################
    <joint name="jLeftGasMed_LF" type="fixed">
        <origin xyz="0 0 0" rpy="0 0 0"/>
        <parent link="LeftFoot"/>
        <child link="GasMed_LF"/>
        <axis xyz="0 0 0" />  
    </joint>




</robot>